[2024-05-06T10:59:51.541+0000] {local_task_job_runner.py:120} INFO - ::group::Pre task execution logs
[2024-05-06T10:59:51.565+0000] {taskinstance.py:2073} INFO - Dependencies all met for dep_context=non-requeueable deps ti=<TaskInstance: postgres_operator_dag.insert_to_postgres manual__2024-05-06T10:54:44.289137+00:00 [queued]>
[2024-05-06T10:59:51.575+0000] {taskinstance.py:2073} INFO - Dependencies all met for dep_context=requeueable deps ti=<TaskInstance: postgres_operator_dag.insert_to_postgres manual__2024-05-06T10:54:44.289137+00:00 [queued]>
[2024-05-06T10:59:51.577+0000] {taskinstance.py:2303} INFO - Starting attempt 2 of 3
[2024-05-06T10:59:51.590+0000] {taskinstance.py:2327} INFO - Executing <Task(PythonOperator): insert_to_postgres> on 2024-05-06 10:54:44.289137+00:00
[2024-05-06T10:59:51.595+0000] {warnings.py:110} WARNING - /home/***/.local/lib/python3.12/site-packages/***/task/task_runner/standard_task_runner.py:61: DeprecationWarning: This process (pid=1030) is multi-threaded, use of fork() may lead to deadlocks in the child.
  pid = os.fork()

[2024-05-06T10:59:51.597+0000] {standard_task_runner.py:63} INFO - Started process 1031 to run task
[2024-05-06T10:59:51.597+0000] {standard_task_runner.py:90} INFO - Running: ['***', 'tasks', 'run', 'postgres_operator_dag', 'insert_to_postgres', 'manual__2024-05-06T10:54:44.289137+00:00', '--job-id', '112', '--raw', '--subdir', 'DAGS_FOLDER/kachevo.py', '--cfg-path', '/tmp/tmpwd3hyq7n']
[2024-05-06T10:59:51.599+0000] {standard_task_runner.py:91} INFO - Job 112: Subtask insert_to_postgres
[2024-05-06T10:59:51.640+0000] {task_command.py:426} INFO - Running <TaskInstance: postgres_operator_dag.insert_to_postgres manual__2024-05-06T10:54:44.289137+00:00 [running]> on host db2363de7199
[2024-05-06T10:59:51.720+0000] {taskinstance.py:2644} INFO - Exporting env vars: AIRFLOW_CTX_DAG_OWNER='***' AIRFLOW_CTX_DAG_ID='postgres_operator_dag' AIRFLOW_CTX_TASK_ID='insert_to_postgres' AIRFLOW_CTX_EXECUTION_DATE='2024-05-06T10:54:44.289137+00:00' AIRFLOW_CTX_TRY_NUMBER='2' AIRFLOW_CTX_DAG_RUN_ID='manual__2024-05-06T10:54:44.289137+00:00'
[2024-05-06T10:59:51.721+0000] {taskinstance.py:430} INFO - ::endgroup::
[2024-05-06T10:59:51.750+0000] {base.py:84} INFO - Using connection ID 'postgres' for task execution.
[2024-05-06T10:59:51.898+0000] {taskinstance.py:441} INFO - ::group::Post task execution logs
[2024-05-06T10:59:51.899+0000] {taskinstance.py:2890} ERROR - Task failed with exception
Traceback (most recent call last):
  File "/home/airflow/.local/lib/python3.12/site-packages/airflow/models/taskinstance.py", line 465, in _execute_task
    result = _execute_callable(context=context, **execute_callable_kwargs)
             ^^^^^^^^^^^^^^^^^^^^^^^^^^^^^^^^^^^^^^^^^^^^^^^^^^^^^^^^^^^^^
  File "/home/airflow/.local/lib/python3.12/site-packages/airflow/models/taskinstance.py", line 432, in _execute_callable
    return execute_callable(context=context, **execute_callable_kwargs)
           ^^^^^^^^^^^^^^^^^^^^^^^^^^^^^^^^^^^^^^^^^^^^^^^^^^^^^^^^^^^^
  File "/home/airflow/.local/lib/python3.12/site-packages/airflow/models/baseoperator.py", line 400, in wrapper
    return func(self, *args, **kwargs)
           ^^^^^^^^^^^^^^^^^^^^^^^^^^^
  File "/home/airflow/.local/lib/python3.12/site-packages/airflow/operators/python.py", line 235, in execute
    return_value = self.execute_callable()
                   ^^^^^^^^^^^^^^^^^^^^^^^
  File "/home/airflow/.local/lib/python3.12/site-packages/airflow/operators/python.py", line 252, in execute_callable
    return self.python_callable(*self.op_args, **self.op_kwargs)
           ^^^^^^^^^^^^^^^^^^^^^^^^^^^^^^^^^^^^^^^^^^^^^^^^^^^^^
  File "/opt/airflow/dags/kachevo.py", line 72, in insert_to_postgres
    cursor.execute("INSERT INTO pet VALUES (%s)", mysql_result)
psycopg2.errors.DatatypeMismatch: ОШИБКА:  столбец "pet_id" имеет тип integer, а выражение - record
LINE 1: INSERT INTO pet VALUES ((1, 'Samurai', 'Dog', '2010-08-11'::...
                                ^
HINT:  Перепишите выражение или преобразуйте его тип.

[2024-05-06T10:59:51.911+0000] {taskinstance.py:1205} INFO - Marking task as UP_FOR_RETRY. dag_id=postgres_operator_dag, task_id=insert_to_postgres, execution_date=20240506T105444, start_date=20240506T105951, end_date=20240506T105951
[2024-05-06T10:59:51.924+0000] {standard_task_runner.py:110} ERROR - Failed to execute job 112 for task insert_to_postgres (ОШИБКА:  столбец "pet_id" имеет тип integer, а выражение - record
LINE 1: INSERT INTO pet VALUES ((1, 'Samurai', 'Dog', '2010-08-11'::...
                                ^
HINT:  Перепишите выражение или преобразуйте его тип.
; 1031)
[2024-05-06T10:59:51.972+0000] {local_task_job_runner.py:240} INFO - Task exited with return code 1
[2024-05-06T10:59:51.990+0000] {taskinstance.py:3482} INFO - 0 downstream tasks scheduled from follow-on schedule check
[2024-05-06T10:59:51.992+0000] {local_task_job_runner.py:222} INFO - ::endgroup::
