[2024-05-06T12:10:09.775+0000] {local_task_job_runner.py:120} INFO - ::group::Pre task execution logs
[2024-05-06T12:10:09.796+0000] {taskinstance.py:2073} INFO - Dependencies all met for dep_context=non-requeueable deps ti=<TaskInstance: postgres_operator_dag.insert_to_postgres manual__2024-05-06T12:09:58.649390+00:00 [queued]>
[2024-05-06T12:10:09.806+0000] {taskinstance.py:2073} INFO - Dependencies all met for dep_context=requeueable deps ti=<TaskInstance: postgres_operator_dag.insert_to_postgres manual__2024-05-06T12:09:58.649390+00:00 [queued]>
[2024-05-06T12:10:09.807+0000] {taskinstance.py:2303} INFO - Starting attempt 1 of 3
[2024-05-06T12:10:09.822+0000] {taskinstance.py:2327} INFO - Executing <Task(PythonOperator): insert_to_postgres> on 2024-05-06 12:09:58.649390+00:00
[2024-05-06T12:10:09.829+0000] {warnings.py:110} WARNING - /home/***/.local/lib/python3.12/site-packages/***/task/task_runner/standard_task_runner.py:61: DeprecationWarning: This process (pid=2134) is multi-threaded, use of fork() may lead to deadlocks in the child.
  pid = os.fork()

[2024-05-06T12:10:09.830+0000] {standard_task_runner.py:63} INFO - Started process 2135 to run task
[2024-05-06T12:10:09.830+0000] {standard_task_runner.py:90} INFO - Running: ['***', 'tasks', 'run', 'postgres_operator_dag', 'insert_to_postgres', 'manual__2024-05-06T12:09:58.649390+00:00', '--job-id', '205', '--raw', '--subdir', 'DAGS_FOLDER/kachevo.py', '--cfg-path', '/tmp/tmp5npi_q4m']
[2024-05-06T12:10:09.833+0000] {standard_task_runner.py:91} INFO - Job 205: Subtask insert_to_postgres
[2024-05-06T12:10:09.878+0000] {task_command.py:426} INFO - Running <TaskInstance: postgres_operator_dag.insert_to_postgres manual__2024-05-06T12:09:58.649390+00:00 [running]> on host db2363de7199
[2024-05-06T12:10:09.959+0000] {taskinstance.py:2644} INFO - Exporting env vars: AIRFLOW_CTX_DAG_OWNER='***' AIRFLOW_CTX_DAG_ID='postgres_operator_dag' AIRFLOW_CTX_TASK_ID='insert_to_postgres' AIRFLOW_CTX_EXECUTION_DATE='2024-05-06T12:09:58.649390+00:00' AIRFLOW_CTX_TRY_NUMBER='1' AIRFLOW_CTX_DAG_RUN_ID='manual__2024-05-06T12:09:58.649390+00:00'
[2024-05-06T12:10:09.960+0000] {taskinstance.py:430} INFO - ::endgroup::
[2024-05-06T12:10:09.996+0000] {base.py:84} INFO - Using connection ID 'postgres' for task execution.
[2024-05-06T12:10:10.042+0000] {taskinstance.py:441} INFO - ::group::Post task execution logs
[2024-05-06T12:10:10.043+0000] {taskinstance.py:2890} ERROR - Task failed with exception
Traceback (most recent call last):
  File "/home/airflow/.local/lib/python3.12/site-packages/airflow/models/taskinstance.py", line 465, in _execute_task
    result = _execute_callable(context=context, **execute_callable_kwargs)
             ^^^^^^^^^^^^^^^^^^^^^^^^^^^^^^^^^^^^^^^^^^^^^^^^^^^^^^^^^^^^^
  File "/home/airflow/.local/lib/python3.12/site-packages/airflow/models/taskinstance.py", line 432, in _execute_callable
    return execute_callable(context=context, **execute_callable_kwargs)
           ^^^^^^^^^^^^^^^^^^^^^^^^^^^^^^^^^^^^^^^^^^^^^^^^^^^^^^^^^^^^
  File "/home/airflow/.local/lib/python3.12/site-packages/airflow/models/baseoperator.py", line 400, in wrapper
    return func(self, *args, **kwargs)
           ^^^^^^^^^^^^^^^^^^^^^^^^^^^
  File "/home/airflow/.local/lib/python3.12/site-packages/airflow/operators/python.py", line 235, in execute
    return_value = self.execute_callable()
                   ^^^^^^^^^^^^^^^^^^^^^^^
  File "/home/airflow/.local/lib/python3.12/site-packages/airflow/operators/python.py", line 252, in execute_callable
    return self.python_callable(*self.op_args, **self.op_kwargs)
           ^^^^^^^^^^^^^^^^^^^^^^^^^^^^^^^^^^^^^^^^^^^^^^^^^^^^^
  File "/opt/airflow/dags/kachevo.py", line 114, in insert_to_postgres
    cursor.execute("INSERT INTO pet (pet_id, name, pet_type, birth_date, owner) VALUES (%s, %s, %s, %s, %s)", mysql_result[0])
psycopg2.errors.UniqueViolation: ОШИБКА:  повторяющееся значение ключа нарушает ограничение уникальности "pet_pkey"
DETAIL:  Ключ "(pet_id)=(1)" уже существует.

[2024-05-06T12:10:10.055+0000] {taskinstance.py:1205} INFO - Marking task as UP_FOR_RETRY. dag_id=postgres_operator_dag, task_id=insert_to_postgres, execution_date=20240506T120958, start_date=20240506T121009, end_date=20240506T121010
[2024-05-06T12:10:10.067+0000] {standard_task_runner.py:110} ERROR - Failed to execute job 205 for task insert_to_postgres (ОШИБКА:  повторяющееся значение ключа нарушает ограничение уникальности "pet_pkey"
DETAIL:  Ключ "(pet_id)=(1)" уже существует.
; 2135)
[2024-05-06T12:10:10.085+0000] {local_task_job_runner.py:240} INFO - Task exited with return code 1
[2024-05-06T12:10:10.108+0000] {taskinstance.py:3482} INFO - 0 downstream tasks scheduled from follow-on schedule check
[2024-05-06T12:10:10.110+0000] {local_task_job_runner.py:222} INFO - ::endgroup::
