[2024-05-05T14:05:05.116+0000] {local_task_job_runner.py:120} INFO - ::group::Pre task execution logs
[2024-05-05T14:05:05.140+0000] {taskinstance.py:2073} INFO - Dependencies all met for dep_context=non-requeueable deps ti=<TaskInstance: postgres_operator_dag.get_all_pets manual__2024-05-05T14:04:59.541581+00:00 [queued]>
[2024-05-05T14:05:05.149+0000] {taskinstance.py:2073} INFO - Dependencies all met for dep_context=requeueable deps ti=<TaskInstance: postgres_operator_dag.get_all_pets manual__2024-05-05T14:04:59.541581+00:00 [queued]>
[2024-05-05T14:05:05.150+0000] {taskinstance.py:2303} INFO - Starting attempt 1 of 1
[2024-05-05T14:05:05.163+0000] {taskinstance.py:2327} INFO - Executing <Task(PostgresOperator): get_all_pets> on 2024-05-05 14:04:59.541581+00:00
[2024-05-05T14:05:05.169+0000] {warnings.py:110} WARNING - /home/***/.local/lib/python3.12/site-packages/***/task/task_runner/standard_task_runner.py:61: DeprecationWarning: This process (pid=134) is multi-threaded, use of fork() may lead to deadlocks in the child.
  pid = os.fork()

[2024-05-05T14:05:05.171+0000] {standard_task_runner.py:63} INFO - Started process 135 to run task
[2024-05-05T14:05:05.170+0000] {standard_task_runner.py:90} INFO - Running: ['***', 'tasks', 'run', 'postgres_operator_dag', 'get_all_pets', 'manual__2024-05-05T14:04:59.541581+00:00', '--job-id', '36', '--raw', '--subdir', 'DAGS_FOLDER/kachevo.py', '--cfg-path', '/tmp/tmpafi8o3v0']
[2024-05-05T14:05:05.172+0000] {standard_task_runner.py:91} INFO - Job 36: Subtask get_all_pets
[2024-05-05T14:05:05.220+0000] {task_command.py:426} INFO - Running <TaskInstance: postgres_operator_dag.get_all_pets manual__2024-05-05T14:04:59.541581+00:00 [running]> on host db2363de7199
[2024-05-05T14:05:05.298+0000] {taskinstance.py:2644} INFO - Exporting env vars: AIRFLOW_CTX_DAG_OWNER='***' AIRFLOW_CTX_DAG_ID='postgres_operator_dag' AIRFLOW_CTX_TASK_ID='get_all_pets' AIRFLOW_CTX_EXECUTION_DATE='2024-05-05T14:04:59.541581+00:00' AIRFLOW_CTX_TRY_NUMBER='1' AIRFLOW_CTX_DAG_RUN_ID='manual__2024-05-05T14:04:59.541581+00:00'
[2024-05-05T14:05:05.299+0000] {taskinstance.py:430} INFO - ::endgroup::
[2024-05-05T14:05:05.311+0000] {sql.py:276} INFO - Executing: SELECT * FROM pet;
[2024-05-05T14:05:05.320+0000] {taskinstance.py:441} INFO - ::group::Post task execution logs
[2024-05-05T14:05:05.329+0000] {taskinstance.py:2890} ERROR - Task failed with exception
Traceback (most recent call last):
  File "/home/airflow/.local/lib/python3.12/site-packages/airflow/models/taskinstance.py", line 465, in _execute_task
    result = _execute_callable(context=context, **execute_callable_kwargs)
             ^^^^^^^^^^^^^^^^^^^^^^^^^^^^^^^^^^^^^^^^^^^^^^^^^^^^^^^^^^^^^
  File "/home/airflow/.local/lib/python3.12/site-packages/airflow/models/taskinstance.py", line 432, in _execute_callable
    return execute_callable(context=context, **execute_callable_kwargs)
           ^^^^^^^^^^^^^^^^^^^^^^^^^^^^^^^^^^^^^^^^^^^^^^^^^^^^^^^^^^^^
  File "/home/airflow/.local/lib/python3.12/site-packages/airflow/models/baseoperator.py", line 400, in wrapper
    return func(self, *args, **kwargs)
           ^^^^^^^^^^^^^^^^^^^^^^^^^^^
  File "/home/airflow/.local/lib/python3.12/site-packages/airflow/providers/common/sql/operators/sql.py", line 277, in execute
    hook = self.get_db_hook()
           ^^^^^^^^^^^^^^^^^^
  File "/home/airflow/.local/lib/python3.12/site-packages/airflow/providers/common/sql/operators/sql.py", line 188, in get_db_hook
    return self._hook
           ^^^^^^^^^^
  File "/usr/local/lib/python3.12/functools.py", line 995, in __get__
    val = self.func(instance)
          ^^^^^^^^^^^^^^^^^^^
  File "/home/airflow/.local/lib/python3.12/site-packages/airflow/providers/common/sql/operators/sql.py", line 150, in _hook
    conn = BaseHook.get_connection(conn_id)
           ^^^^^^^^^^^^^^^^^^^^^^^^^^^^^^^^
  File "/home/airflow/.local/lib/python3.12/site-packages/airflow/hooks/base.py", line 83, in get_connection
    conn = Connection.get_connection_from_secrets(conn_id)
           ^^^^^^^^^^^^^^^^^^^^^^^^^^^^^^^^^^^^^^^^^^^^^^^
  File "/home/airflow/.local/lib/python3.12/site-packages/airflow/models/connection.py", line 519, in get_connection_from_secrets
    raise AirflowNotFoundException(f"The conn_id `{conn_id}` isn't defined")
airflow.exceptions.AirflowNotFoundException: The conn_id `postgres_default` isn't defined
[2024-05-05T14:05:05.335+0000] {taskinstance.py:1205} INFO - Marking task as FAILED. dag_id=postgres_operator_dag, task_id=get_all_pets, execution_date=20240505T140459, start_date=20240505T140505, end_date=20240505T140505
[2024-05-05T14:05:05.350+0000] {standard_task_runner.py:110} ERROR - Failed to execute job 36 for task get_all_pets (The conn_id `postgres_default` isn't defined; 135)
[2024-05-05T14:05:05.386+0000] {local_task_job_runner.py:240} INFO - Task exited with return code 1
[2024-05-05T14:05:05.401+0000] {warnings.py:110} WARNING - /home/***/.local/lib/python3.12/site-packages/***/models/baseoperator.py:1296: AirflowProviderDeprecationWarning: Call to deprecated class PostgresOperator. (Please use `***.providers.common.sql.operators.sql.SQLExecuteQueryOperator`.Also, you can provide `hook_params={'schema': <database>}`.)
  result = cls.__new__(cls)

[2024-05-05T14:05:05.414+0000] {taskinstance.py:3482} INFO - 0 downstream tasks scheduled from follow-on schedule check
[2024-05-05T14:05:05.421+0000] {local_task_job_runner.py:222} INFO - ::endgroup::
