[2024-05-06T11:39:31.701+0000] {local_task_job_runner.py:120} INFO - ::group::Pre task execution logs
[2024-05-06T11:39:31.729+0000] {taskinstance.py:2073} INFO - Dependencies all met for dep_context=non-requeueable deps ti=<TaskInstance: postgres_operator_dag.insert_to_postgres manual__2024-05-06T11:29:02.907851+00:00 [queued]>
[2024-05-06T11:39:31.741+0000] {taskinstance.py:2073} INFO - Dependencies all met for dep_context=requeueable deps ti=<TaskInstance: postgres_operator_dag.insert_to_postgres manual__2024-05-06T11:29:02.907851+00:00 [queued]>
[2024-05-06T11:39:31.742+0000] {taskinstance.py:2303} INFO - Starting attempt 3 of 3
[2024-05-06T11:39:31.754+0000] {taskinstance.py:2327} INFO - Executing <Task(PythonOperator): insert_to_postgres> on 2024-05-06 11:29:02.907851+00:00
[2024-05-06T11:39:31.760+0000] {warnings.py:110} WARNING - /home/***/.local/lib/python3.12/site-packages/***/task/task_runner/standard_task_runner.py:61: DeprecationWarning: This process (pid=1622) is multi-threaded, use of fork() may lead to deadlocks in the child.
  pid = os.fork()

[2024-05-06T11:39:31.761+0000] {standard_task_runner.py:63} INFO - Started process 1625 to run task
[2024-05-06T11:39:31.761+0000] {standard_task_runner.py:90} INFO - Running: ['***', 'tasks', 'run', 'postgres_operator_dag', 'insert_to_postgres', 'manual__2024-05-06T11:29:02.907851+00:00', '--job-id', '149', '--raw', '--subdir', 'DAGS_FOLDER/kachevo.py', '--cfg-path', '/tmp/tmpzc4c7v87']
[2024-05-06T11:39:31.763+0000] {standard_task_runner.py:91} INFO - Job 149: Subtask insert_to_postgres
[2024-05-06T11:39:31.804+0000] {task_command.py:426} INFO - Running <TaskInstance: postgres_operator_dag.insert_to_postgres manual__2024-05-06T11:29:02.907851+00:00 [running]> on host db2363de7199
[2024-05-06T11:39:31.882+0000] {taskinstance.py:2644} INFO - Exporting env vars: AIRFLOW_CTX_DAG_OWNER='***' AIRFLOW_CTX_DAG_ID='postgres_operator_dag' AIRFLOW_CTX_TASK_ID='insert_to_postgres' AIRFLOW_CTX_EXECUTION_DATE='2024-05-06T11:29:02.907851+00:00' AIRFLOW_CTX_TRY_NUMBER='3' AIRFLOW_CTX_DAG_RUN_ID='manual__2024-05-06T11:29:02.907851+00:00'
[2024-05-06T11:39:31.884+0000] {taskinstance.py:430} INFO - ::endgroup::
[2024-05-06T11:39:31.914+0000] {base.py:84} INFO - Using connection ID 'postgres' for task execution.
[2024-05-06T11:39:31.960+0000] {taskinstance.py:441} INFO - ::group::Post task execution logs
[2024-05-06T11:39:31.961+0000] {taskinstance.py:2890} ERROR - Task failed with exception
Traceback (most recent call last):
  File "/home/airflow/.local/lib/python3.12/site-packages/airflow/models/taskinstance.py", line 465, in _execute_task
    result = _execute_callable(context=context, **execute_callable_kwargs)
             ^^^^^^^^^^^^^^^^^^^^^^^^^^^^^^^^^^^^^^^^^^^^^^^^^^^^^^^^^^^^^
  File "/home/airflow/.local/lib/python3.12/site-packages/airflow/models/taskinstance.py", line 432, in _execute_callable
    return execute_callable(context=context, **execute_callable_kwargs)
           ^^^^^^^^^^^^^^^^^^^^^^^^^^^^^^^^^^^^^^^^^^^^^^^^^^^^^^^^^^^^
  File "/home/airflow/.local/lib/python3.12/site-packages/airflow/models/baseoperator.py", line 400, in wrapper
    return func(self, *args, **kwargs)
           ^^^^^^^^^^^^^^^^^^^^^^^^^^^
  File "/home/airflow/.local/lib/python3.12/site-packages/airflow/operators/python.py", line 235, in execute
    return_value = self.execute_callable()
                   ^^^^^^^^^^^^^^^^^^^^^^^
  File "/home/airflow/.local/lib/python3.12/site-packages/airflow/operators/python.py", line 252, in execute_callable
    return self.python_callable(*self.op_args, **self.op_kwargs)
           ^^^^^^^^^^^^^^^^^^^^^^^^^^^^^^^^^^^^^^^^^^^^^^^^^^^^^
  File "/opt/airflow/dags/kachevo.py", line 84, in insert_to_postgres
    cursor.execute("INSERT INTO pet (pet_id, name, pet_type, birth_date, owner) VALUES (%s, %s, %s, %s, %s)", mysql_result[0])
psycopg2.errors.UniqueViolation: ОШИБКА:  повторяющееся значение ключа нарушает ограничение уникальности "pet_pkey"
DETAIL:  Ключ "(pet_id)=(1)" уже существует.

[2024-05-06T11:39:31.972+0000] {taskinstance.py:1205} INFO - Marking task as FAILED. dag_id=postgres_operator_dag, task_id=insert_to_postgres, execution_date=20240506T112902, start_date=20240506T113931, end_date=20240506T113931
[2024-05-06T11:39:31.991+0000] {standard_task_runner.py:110} ERROR - Failed to execute job 149 for task insert_to_postgres (ОШИБКА:  повторяющееся значение ключа нарушает ограничение уникальности "pet_pkey"
DETAIL:  Ключ "(pet_id)=(1)" уже существует.
; 1625)
[2024-05-06T11:39:32.016+0000] {local_task_job_runner.py:240} INFO - Task exited with return code 1
[2024-05-06T11:39:32.030+0000] {taskinstance.py:3482} INFO - 0 downstream tasks scheduled from follow-on schedule check
[2024-05-06T11:39:32.032+0000] {local_task_job_runner.py:222} INFO - ::endgroup::
