[2024-05-06T11:08:37.723+0000] {task_context_logger.py:104} ERROR - Executor reports task instance <TaskInstance: postgres_operator_dag.insert_to_postgres manual__2024-05-06T10:58:28.722040+00:00 [queued]> finished (failed) although the task says it's queued. (Info: None) Was the task killed externally?
